<mujoco model="ur5e">
<compiler angle="radian" meshdir="meshes" autolimits="true"/>

  <option integrator="implicitfast"/>

  <default>
    <default class="ur5e">
      <default class="visual">
        <geom type="mesh" contype="0" conaffinity="0" group="2"/>
      </default>
      <default class="collision">
        <geom type="mesh" group="3"/>
      </default>
      <joint axis="0 1 0" range="-6.28319 6.28319"/>
      <default class="joint_limited">
        <joint range="-3.1415 3.1415"/>
      </default>
      <default class="finger_joint">
        <joint range="-1 0"/>
      </default>
    </default>
  </default>

  <asset>
    <material name="black" rgba="0.033 0.033 0.033 1"/>
    <material name="jointgray" rgba="0.278 0.278 0.278 1"/>
    <material name="linkgray" rgba="0.82 0.82 0.82 1"/>
    <material name="urblue" rgba="0.49 0.678 0.8 1"/>
        <!--Meshes-->
        <!--Forearm-->
        <mesh name="base"           file="base.stl"     />
        <mesh name="shoulder"       file="shoulder.stl" />
        <mesh name="upperarm"       file="upperarm.stl" />
        <mesh name="forearm"        file="forearm.stl"  />
        <mesh name="wrist1"         file="wrist1.stl"   />
        <mesh name="wrist2"         file="wrist2.stl"   />
        <mesh name="wrist3"         file="wrist3.stl"   />
        <!--Palm-->
        <mesh name="robotiq_85_base_link_coarse" file="robotiq_85_base_link_coarse.stl" />
        <mesh name="inner_knuckle_coarse" file="inner_knuckle_coarse.stl" />
        <mesh name="inner_finger_coarse" file="inner_finger_coarse.stl" />
  </asset>

  <worldbody>
    <body name="base" pos="0 0 0.085" childclass="ur5e">
      <inertial mass="4" pos="0 0 0" quat="0.5 0.5 -0.5 0.5" diaginertia="0.0072 0.00443333 0.00443333"/>
      <geom mesh="base" material="black" class="collision"/>
      <geom mesh="base" material="black" class="visual"/>
      <body name="shoulder_link" pos="0 0 0.193">
        <inertial mass="3.7" pos="0 0 0" diaginertia="0.0102675 0.0102675 0.00666"/>
        <joint name="shoulder_pan" axis="0 0 1"/>
        <geom mesh="shoulder" material="urblue" class="collision"/>
        <geom mesh="shoulder" material="urblue" class="visual"/>
        <body name="upper_arm_link" pos="0 0.13585 0" quat="0.707107 0 0.707107 0">
          <inertial mass="8.393" pos="0 0 0.28" diaginertia="0.226891 0.226891 0.0151074" />
          <joint name="shoulder_lift"/>
          <geom mesh="upperarm" material="linkgray" class="collision"/>
          <geom mesh="upperarm" material="linkgray" class="visual"/>
          <body name="forearm_link" pos="0 -0.1197 0.425">
            <inertial pos="0 0 0.25" mass="2.275" diaginertia="0.0494433 0.0494433 0.004095" />
            <joint name="elbow" class="joint_limited"/>
            <geom mesh="forearm" material="urblue" class="collision"/>
            <geom mesh="forearm" material="urblue" class="visual"/>
              <body name="wrist_1_link" pos="0 0 0.39225" quat="0.707107 0 0.707107 0">
              <inertial pos="0 0 0" quat="0.5 0.5 -0.5 0.5" mass="1.219" diaginertia="0.21942 0.111173 0.111173" />
              <joint name="wrist_1"/>
              <geom mesh="wrist1" material="black" class="collision"/>
              <geom mesh="wrist1" material="black" class="visual"/>
              <body name="wrist_2_link" pos="0 0.093 0">
                <inertial pos="0 0 0" quat="0.5 0.5 -0.5 0.5" mass="1.219" diaginertia="0.21942 0.111173 0.111173" />
                <joint name="wrist_2" axis="0 0 1"/>
                <geom mesh="wrist2" material="urblue" class="collision"/>
                <geom mesh="wrist2" material="urblue" class="visual"/>
                <body name="wrist_3_link" pos="0 0 0.09465">
                  <inertial pos="0 0 0" quat="0.5 0.5 -0.5 0.5" mass="0.1879" diaginertia="0.033822 0.0171365 0.0171365" />
                  <joint name="wrist_3"/>
                  <geom material="linkgray" mesh="wrist3" class="collision"/>
                  <geom material="linkgray" mesh="wrist3" class="visual"/>
                  <!--EE LINK-->
                  <body name="ee_link" pos="0 0.0823 0" quat="0.707107 0 0 0.707107">
                  <inertial pos="-0.01 0 0" mass="0.001" diaginertia="1.66667e-08 1.66667e-08 1.66667e-08" />
                  <geom size="0.005 0.005 0.005" pos="-0.01 0 0" type="box"  class="collision"/>
                  <geom size="0.005 0.005 0.005" pos="-0.01 0 0" type="box"  class="visual"/>
                  <body name="robotiq_85_base_link" pos="0 0 0" quat="0.5 0.5 0.5 0.5 ">
                  <inertial pos="0 0 0" quat="0.5 0.5 -0.5 0.5" mass="0.1879" diaginertia="0.033822 0.0171365 0.0171365" />
                      <geom type="mesh" rgba="0.1 0.1 0.1 1" friction="0.8 0.8 0.8" mesh="robotiq_85_base_link_coarse"   class="collision"/>
                      <geom type="mesh" rgba="0.1 0.1 0.1 1" friction="0.8 0.8 0.8" mesh="robotiq_85_base_link_coarse"   class="visual"/>

                      <body name="left_inner_knuckle" pos="0.0127 0 0.0693075">
                          <inertial pos="0 0 0" quat="0.5 0.5 -0.5 0.5" mass="0.1879" diaginertia="0.033822 0.0171365 0.0171365" />
                          <geom type="mesh" rgba="0.1 0.1 0.1 1" friction="0.8 0.8 0.8" mesh="inner_knuckle_coarse" class="collision"/>
                          <geom type="mesh" rgba="0.1 0.1 0.1 1" friction="0.8 0.8 0.8" mesh="inner_knuckle_coarse" class="visual"/>
                          <joint name="base_to_lik" class="finger_joint"/>

                          <body name="left_inner_finger" pos="0.0345853 0 0.045497" >
                              <inertial pos="0.00602756 0 0.00669926"  quat="0.699065 0.106339 0.106339 0.699065" mass="0.00724255" diaginertia="1.70064e-06 1.58577e-06 3.69621e-07" />
                              <geom type="mesh" rgba="0.1 0.1 0.1 1" friction="0.8 0.8 0.8" mesh="inner_finger_coarse"  class="collision"/>
                              <geom type="mesh" rgba="0.1 0.1 0.1 1" friction="0.8 0.8 0.8" mesh="inner_finger_coarse"  class="visual"/>
                          </body>
                      </body>

                      <body name="right_inner_knuckle" pos="-0.0127 0 0.0693075" quat="0 0 0 1">
                          <inertial pos="0 0 0" quat="0.5 0.5 -0.5 0.5" mass="0.1879" diaginertia="0.033822 0.0171365 0.0171365" />
                          <geom type="mesh" friction="0.8 0.8 0.8" mesh="inner_knuckle_coarse"   material="black" class="collision"/>
                          <geom type="mesh" friction="0.8 0.8 0.8" mesh="inner_knuckle_coarse"   material="black" class="visual"/>
                          <joint name="base_to_rik"  class="finger_joint"/>

                          <body name="right_inner_finger" pos="0.0345853 0 0.045497" >
                              <inertial pos="0.00602756 0 0.00669926"  quat="0.699065 0.106339 0.106339 0.699065" mass="0.00724255" diaginertia="1.70064e-06 1.58577e-06 3.69621e-07" />
                              <geom type="mesh" rgba="0.1 0.1 0.1 1" friction="0.8 0.8 0.8" mesh="inner_finger_coarse"   class="collision"/>
                              <geom type="mesh" rgba="0.1 0.1 0.1 1" friction="0.8 0.8 0.8" mesh="inner_finger_coarse"   class="visual"/>
                          </body>
                      </body>
                    </body>
                  </body>
                  <!--EE LINK-->
                </body>
              </body>
            </body>
          </body>
        </body>
      </body>
    </body>
  </worldbody>
</mujoco>
